Workbook

Sheet summary
A1: Dataset Size
B2: Count
A3: # Problems | B3: =COUNT(problems!A:A) -> 69
A4: # Buggy Submissions | B4: =COUNT(buggy_submissions!A:A) -> 366
A6: Repair Coverage
A7: Num Iterations | B7: GPT-4
B8: Success
A9: 1 | B9: =COUNTIFS(gpt4_N!G:G, TRUE, gpt4_N!F:F, "<=1")/$B$4*100 -> 74.863388
A10: 2 | B10: =COUNTIFS(gpt4_N!G:G, TRUE, gpt4_N!F:F, "<=2")/$B$4*100 -> 84.153005
A11: 3 | B11: =COUNTIFS(gpt4_N!G:G, TRUE, gpt4_N!F:F, "<=3")/$B$4*100 -> 86.065574
A12: 4 | B12: =COUNTIFS(gpt4_N!G:G, TRUE, gpt4_N!F:F, "<=4")/$B$4*100 -> 87.978142
A13: 5 | B13: =COUNTIFS(gpt4_N!G:G, TRUE, gpt4_N!F:F, "<=5")/$B$4*100 -> 88.52459
A15: Feedback Confusion Matrix @ 1
C16: GPT-4
C17: Positive | D17: Negative
A18: Actual | B18: Postive | C18: =SUM(gpt4_1!I:I) -> 656 | D18: =SUM(gpt4_1!M:M) -> 125
B19: Negative | C19: =SUM(gpt4_1!J:L) -> 254
A22: Feedback Quality
A23: Num Iterations | B23: GPT-4
B24: Recall | C24: FNR | D24: Precision | E24: FPR-E | F24: FPR-I | G24: FPR-H
A25: Single | B25: =SUM(gpt4_1!$I$1:$I$367)/(SUM(gpt4_1!$I$1:$I$367)+SUM(gpt4_1!M:M)) -> 0.83994878 | C25: =SUM(gpt4_1!M:M)/(SUM(gpt4_1!$I$1:$I$367)+SUM(gpt4_1!M:M)) -> 0.16005122 | D25: =SUM(gpt4_1!$I$1:$I$367)/(SUM(gpt4_1!$I$1:$I$367)+SUM(gpt4_1!$J$1:$L$367)) -> 0.72087912 | E25: =SUM(gpt4_1!$J$1:$J$367)/(SUM(gpt4_1!$I$1:$I$367)+SUM(gpt4_1!$J$1:$L$367)) -> 0.14835165 | F25: =SUM(gpt4_1!$K$1:$K$367)/(SUM(gpt4_1!$I$1:$I$367)+SUM(gpt4_1!$J$1:$L$367)) -> 0.09010989 | G25: =SUM(gpt4_1!$L$1:$L$367)/(SUM(gpt4_1!$I$1:$I$367)+SUM(gpt4_1!$J$1:$L$367)) -> 0.040659341
A26: Multiple | B26: =SUM(gpt4_N!$I$1:$I$367)/(SUM(gpt4_N!$I$1:$I$367)+SUM(gpt4_N!M:M)) -> 0.87169811 | C26: =SUM(gpt4_N!M:M)/(SUM(gpt4_N!$I$1:$I$367)+SUM(gpt4_N!M:M)) -> 0.12830189 | D26: =SUM(gpt4_N!$I$1:$I$367)/(SUM(gpt4_N!$I$1:$I$367)+SUM(gpt4_N!$J$1:$L$367)) -> 0.72413793 | E26: =SUM(gpt4_N!$J$1:$J$367)/(SUM(gpt4_N!$I$1:$I$367)+SUM(gpt4_N!$J$1:$L$367)) -> 0.14420063 | F26: =SUM(gpt4_N!$K$1:$K$367)/(SUM(gpt4_N!$I$1:$I$367)+SUM(gpt4_N!$J$1:$L$367)) -> 0.077324974 | G26: =SUM(gpt4_N!$L$1:$L$367)/(SUM(gpt4_N!$I$1:$I$367)+SUM(gpt4_N!$J$1:$L$367)) -> 0.054336468

Sheet problems
A1: pid | B1: description | C1: prefix | D1: suffix
A2: 17311 | B2: Create a Python program that performs the following operations. First, it should prompt the user to input a temperature in Fahrenheit. Then, it should calculate the equivalent temperature in Celsius and store this value in a variable named 'result'. Finally, the program should print out the calculated Celsius temperature. The formula to convert Fahrenheit to Celsius is given by: T(C) = (T(F) - 32) * 5/9. | C2: globcount = 0 def overriden_input(x): global globcount if(globcount == 0): globcount +=1 return 854 def overriden_eval(x): return x import __future__ input = overriden_input eval = overriden_eval | D2: no_code = False if(globcount == 0): no_code = True ans = (854 - 32) * 5 / 9
A3: 17312 | B3: Create a Python program that accomplishes the following tasks: First, it should prompt the user to input their name. Secondly, it should ask the user to input their age. After collecting these inputs, the program should store a message in the format "My friend <name> is <age> years old." in a variable named 'result'. Finally, the program should print out this message. | C3: globcount = 0 # append the required inputs to the list below return_val = ["Jane", "15"] def overriden_input(x): global globcount globcount += 1 return return_val[globcount - 1] def overriden_eval(x): return x import __future__ input = overriden_input eval = overriden_eval | D3: no_code = False if(globcount == 0): no_code = True ans = "My friend Jane is 15 years old."
A4: 17313 | B4: Create a program that carries out the following operations: It first prompts the user to input the radius of a cylinder. Then, it asks the user to provide the height of the cylinder. The program should then calculate the volume of the cylinder using the formula (πr²h) and store the result in a variable named 'result'. Finally, the program should print out the calculated volume. For this task, use the value of π as 3.14159. | C4: globcount = 0 # append the required inputs to the list below return_val = [8.9, 17] def overriden_input(x): global globcount globcount += 1 return return_val[globcount - 1] def overriden_eval(x): return x import __future__ input = overriden_input eval = overriden_eval | D4: no_code = False if(globcount == 0): no_code = True ans = 3.14159 * 8.9 ** 2 * 17
A5: 17314 | B5: Your task is to create a function named 'count_substring' that calculates the number of substrings within a given string that start with the character 'A' and end with the character 'X'. For instance, if the input string is "CAXAAYXZA", the function should identify four substrings that start with 'A' and end with 'X'. These are: "AX", "AXAAYX", "AAYX", and "AYX". You should accomplish this task using only one loop. The input string will only consist of uppercase English letters.
A6: 17315 | B6: Your task is to create a program that calculates the factorial of a number using a loop. The factorial of a number is the product of all positive integers up to that number. For instance, the factorial of 5 is 1*2*3*4*5 = 120. You can assume that the input will always be a valid positive integer. You should use a 'for' loop to solve this problem. | D6: def big(): x = 1 for i in range(1, 10001): x *= i return x
A7: 17316 | B7: Your task is to create a program that performs the following operations. First, it should prompt the user to input an integer within the range of 0 to 999. Next, the program should add all the digits in the input integer and store the sum in a variable named 'result'. Finally, the program should display the sum of the digits. For instance, if the input integer is 932, the sum of all its digits is 14. To accomplish this, you can use the '%' operator to extract the digits and the '//' operator to remove the extracted digit. Here's an example of how the program should run: Enter a number in range [0,999]: 999 The sum of the digits is 27 | C7: globcount = 0 # append the required inputs to the list below return_val = [259] def overriden_input(x): global globcount globcount += 1 return return_val[globcount - 1] def overriden_eval(x): return x import __future__ input = overriden_input eval = overriden_eval | D7: no_code = False if(globcount == 0): no_code = True ans = 16
A8: 17317 | B8: Create a program that carries out the following operations: First, it should prompt the user to input an integer. Next, the program should determine whether the entered integer is odd or even, and store the outcome in a variable named 'result'. Finally, the program should display the result, where 'True' indicates that the number is even, and 'False' signifies that it's odd. Remember, you can accomplish this task without using an if-else statement. | C8: globcount = 0 def overriden_input(x): global globcount if(globcount == 0): globcount +=1 return 561 def overriden_eval(x): return x import __future__ input = overriden_input eval = overriden_eval | D8: no_code = False if(globcount == 0): no_code = True ans = False
A9: 17318 | B9: You have two variables, x and y, each containing a random integer value. Your task is to write a piece of code that will exchange the values of these two variables. This means that the value initially held by x should be in y and vice versa. | C9: x = 872 y = 23 | D9: newy = 872 newx = 23
A10: 17319 | B10: Your task is to predict the output of the following Python statements without running them. You will need to understand how Python evaluates expressions and how it handles different data types. Here are the statements you need to evaluate: a) print(3 * 6 == 6.0 * 3.0) b) print(2 > 5 or (1 < 2 and 9 >= 11)) c) print(3 > 4 or (2 < 3 and 9 > 10)) d) print( not (11 % 3 == 2)) e) print("2" + "3" == "23") Write down what you think will be printed for each of these statements. | D10: a_ans = True b_ans = False c_ans = False d_ans = False e_ans = True
A11: 17320 | B11: Your task is to translate a given algebraic expression into a Python expression. The algebraic expression is as follows: (3 + 4x)/5 - (10(y - 5)(a + b + c))/x + 9((4/x) + ((9 + x)/y)) You need to write a Python program that will represent this algebraic expression. Remember to use the correct Python syntax for mathematical operations. | C11: x = 98 y = -91 a = 11 b = 276 c = 124 | D11: ans = (3 + 4 * x) / 5 - 10 * (y - 5) * (a + b + c) / x + 9 * (4 / x + (9 + x) / y)
A12: 17322 | B12: The Chinese zodiac is a repeating cycle of 12 years, with each year being represented by an animal sign: monkey, rooster, dog, pig, rat, ox, tiger, rabbit, dragon, snake, horse, and sheep. Your task is to complete a Python function that determines the zodiac sign based on the input year. The function should update the variable 'zodiacYear' with the correct animal sign corresponding to the input 'year'. For instance, if the input year is 1900, the zodiacYear should be "rat", and if the year is 2015, the zodiacYear should be "sheep".
A13: 17323 | B13: You have two numbers, referred to as 'num1' and 'num2'. Your task is to figure out which of these two numbers is smaller. Once you've determined which number is smaller, assign that number to a variable called 'result'.
A14: 17324 | B14: A leap year is a special year that contains an extra day. In the Gregorian calendar, which is the most commonly used solar calendar, February in a leap year has 29 days instead of the usual 28, making the year 366 days long instead of the usual 365. A year is considered a leap year if it is divisible by 4 and not a century year, or if it is a century year that is divisible by 400. For instance, the year 1600 is a leap year because it is evenly divisible by 400. Likewise, the year 1988 is a leap year because it is evenly divisible by 4 but not by 100. Your task is to complete the code below so that the correct value will be assigned to the variable 'isLeapYear' based on the input 'year'. For instance, 'isLeapYear' should be True if 'year' is 1988 and False if 'year' is 2015.
A15: 17325 | B15: A triangle can be classified into several types based on the lengths of its sides. The types are as follows: 1. Not a triangle: If the length of any side is longer or equal to the sum of the other two sides, it's not a triangle. 2. Equilateral: If all sides of a triangle have the same length, it's an equilateral triangle. 3. Isosceles: If two sides are equal in length and it's not an equilateral triangle, it's an isosceles triangle. 4. Scalene: If all sides are unequal and it's a triangle, it's a scalene triangle. Your task is to complete the code such that the correct value will be updated to the variable 'triangleType' based on the input sides 's1", 's2", and 's3'. For example: - Given sides 5, 5, 5, the 'triangleType' should be "Equilateral". - Given sides 100, 3, 4, the 'triangleType' should be "Not a triangle".
A16: 17326 | B16: In this task, you need to calculate the gradient of a straight line given the coordinates of two points on the line. You are required to complete a code that will update the variable 'gradientType' based on the two input points (x1, y1) and (x2, y2). For instance, if the two points are (2,2) and (1,4), the 'gradientType' should be "Negative". Similarly, if the two points are (2,2) and (4,3), the 'gradientType' should be "Positive".
A17: 17327 | B17: Your task is to create a Python function that checks whether a given point (x, y) is located within a circle. The circle is centered at the origin (0, 0) and has a radius of 10. Based on your check, update a variable named 'inCircle'. If the point is within the circle, 'inCircle' should be True. If the point is outside the circle, 'inCircle' should be False. For instance, the point (4, 5) is inside the circle, so 'inCircle' would be True. However, the point (9, 9) is outside the circle, making 'inCircle' False. | C17: import math
A18: 17329 | B18: Your task is to create a program that can convert a positive integer given in binary format into its equivalent decimal representation. However, there's a catch! You are not permitted to use the built-in 'int' function. For guidance on the input format, please refer to the example test cases provided. | D18: factorial = lambda x: 1 if x <= 1 else x*factorial(x-1)
A19: 17330 | B19: This task is centered around the Fibonacci sequence, a popular concept in mathematics. The Fibonacci sequence is defined as follows: The first and second terms are 1. The nth term is the sum of the (n-1)th term and the (n-2)th term. For example, the third term is the sum of the first and second terms, the fourth term is the sum of the third and second terms, and so on. The sequence begins as follows: "1", 1, 2, 3, 5, 8, 13, 21, ... Your task is to write a program that, given a positive integer n, computes the nth term in the Fibonacci sequence.
A20: 17331 | B20: Your task is to create a function that takes a positive integer as an input and returns the number with its digits in reverse order. For instance, if the input is 12345, your function should return 54321. Please note that you are not permitted to use the built-in 'str' and 'int' functions in Python. Your function should be able to perform this task without converting the integer to a string or vice versa. | D20: def factorial(n): a = 1 for i in range(1, n+1): a *= i return a
A21: 17332 | B21: You are given two positive integers, 'a' and 'b", where 'a' is not greater than 'b'. Your task is to determine how many integers between 'a' and 'b", inclusive, are palindromes. A number is considered a palindrome if it remains the same when its digits are reversed. In other words, a number 'n' is a palindrome if 'n' equals the reverse of 'n'. You can use the 'reverse_number' function from a previous problem as if it is already defined. | C21: def reverse_number(num): n = 0 while num: n*=10 n += num%10 num //= 10 return n
A22: 17337 | B22: Think of a function as a mysterious box. You only need to be aware of the inputs it requires and the output it produces. One method to calculate the area of a triangle is by using the formula: area = 1/2 * base * height. Your task is to define a function named 'area' that uses this formula to calculate and return the area of any given triangle. You need to determine what inputs it needs and what it should return as output.
A23: 17338 | B23: A different approach to calculate the area of a triangle with sides A, B, C involves the use of the trigonometric ratio sine. The formula to calculate the area is 1/2 * A * B * sin(AB), where AB is the angle included between sides A and B. In Python, the 'sin' function is available in the 'math' package. To use it, you need to include the line 'from math import *' at the top of your Python file. Your task is to define a function named 'area2' that calculates and returns the area of any given triangle using this formula. You need to decide what arguments it should take as input and what its return value should be. Once you have both functions, consider if they can be directly substituted for each other and explain why.
A24: 17339 | B24: In this task, you will be implementing a function that calculates the area of a triangle using Heron's Formula. The formula for calculating the area of a triangle using Heron's formula is area = sqrt[s*(s - a)*(s - b)*(s - c)], where s = (a+b+c)/2. You need to define a function named 'area3' that takes the lengths of the three sides of a triangle as arguments and returns the area of the triangle calculated using Heron's formula. You need to decide what the arguments of the function should be and what its return value should be.
A25: 17344 | B25: It's time to put your knowledge into practice! Your task is to use a 'for' loop to calculate the sum of the first 1337 natural numbers. In other words, you need to add all numbers from 1 to 1337. The result should be stored in the variable 'ans' which has already been defined for you.
A26: 17345 | B26: A function named 'mystery' has been defined. This function takes in a single integer as an input and returns False if the input matches a specific integer Z, and True otherwise. It's known that Z lies between 1 and 1000, both inclusive. For instance, if Z equals 201, the function 'mystery(201)' would return False, while other inputs like 'mystery(101)", 'mystery(400)", and 'mystery(2)' would return True. Your task is to use a 'while' loop to identify the value of Z. Start with z equals 1, and continue testing 'mystery(z)' until it returns False. At this point, you have discovered the value of Z. | C26: mystery = lambda x: not (x == 689)
A27: 17346 | B27: Python comes with several built-in functions that can be used with lists. For instance, the 'len' function can be used to return the number of elements in a list, the 'max'/'min' functions can be used to return the elements with the highest and lowest values in the list, and the 'sum' function can return the sum of all elements in the list. Given a list of random numbers named 'myList", your task is to use these functions to determine the length of 'myList", the smallest number in 'myList", the largest number in 'myList", and the sum of all the numbers within 'myList'. | C27: from random import randint myList = [] for i in range(randint(10, 50)): myList.append(randint(0, 100))
A28: 17347 | B28: You are tasked with calculating the area of a regular pentagon. The formula to calculate the area of a regular pentagon is given by ((3 * sqrt(3))/2) * (2*r* sin(pi/5))^2, where r is the radius of the pentagon. You need to store the calculated area in a variable named 'result'. The area should be formatted to 2 decimal places. For instance, if the radius of the pentagon is 5.5, the calculated area should be stored as '51.53' in the 'result' variable. | D28: if r < 0: # Fail if r is negative result = 0 s = 2*r*math.sin(math.pi/5) area = ((3*math.sqrt(3))/2)*s**2 answer = format(area, ".2f")
A29: 17348 | B29: You are required to calculate a certain value and store it in a variable named 'result'. The calculation involves a mathematical formula that uses the number of sides (n) of a regular polygon and the length of each side (s). The formula is: (n*s*s)/(4 * tan(pi/n)). For this task, consider n as 5 and s as 6.5. Once you have calculated the value, format it to 4 decimal places. | D29: if (n < 0 or s < 0): result = 0 area = (n*(s**2))/(4*(math.tan(math.pi/n))) answer = format(area, ".4f")
A30: 17349 | B30: Your task is to create a Python program that generates a random uppercase letter. To accomplish this, you'll need to store the randomly generated uppercase letter in a variable named 'result'. Please remember to keep the letter in uppercase. | D30: r = range(65, 91) if ord(result) in r: answer = chr(ord(result)) else: answer = ""
A31: 17350 | B31: Your task is to create a Python program that generates a random string of 5 lowercase letters. You should store the final string in a variable named 'result'. | D31: r = range(97,123) answer = "" for i in range(5): if ord(result[i]) in r: answer += result[i] #print(i) else: answer = ""
A32: 17351 | B32: Your task is to create a Python program that generates a random string composed of both characters and numbers. The string should adhere to the following format: CCNNNc. In this format, 'C' represents uppercase letters, 'c' represents lowercase letters, and 'N' represents numbers from 0 to 9. It's important to remember to store the result of your program in a variable named 'result'. | D32: r1 = range(97, 123) r2 = range(65, 91) r3 = range(48, 58) answer = "" for i in range(6): if (i < 2 and ord(result[i]) in r2): answer += result[i] elif ((i>= 2 and i<5) and ord(result[i]) in r3): answer += result[i] elif ((i == 5) and ord(result[i]) in r1): answer += result[i] else: answer = ""
A33: 17352 | B33: Your task is to create a string variable named 's'. When this string is printed, it should display the following message: "He said, 'This is nested\annoying'", Steve recalled. Remember to correctly use escape characters to handle quotes and backslashes within the string.
A34: 17353 | B34: Your task is to create a string variable named 's'. This string should consist of 1000 'a' characters followed by 1000 'b' characters. In other words, your string should look like this: 'aaaaa...aaaabbbbb...bbbb", where there are 1000 'a's and 1000 'b's.
A35: 17354 | B35: John has noticed that many of his tweets on Twitter are less than 140 characters long. He wants to make the most of the available space by filling any remaining space with the string 'lolololol' until he reaches 140 characters. For instance, if his message is "What a wonderful day!", he wants to tweet "What a wonderful day!lololololololololololololololololololololololololololololololololololololololololololololololololololololololololololololol". Note that the 'lololol...' part should always end with an 'l'. To achieve this, you may need to leave a space between the message and the start of the 'lolololol...' part. For example, 'Odd' will become 'Oddlololololololololololololololololololololololololololololololololololololololololololololololololololololololololololololololololololol' (without space), and 'Even' will become 'Even lolololololololololololololololololololololololololololololololololololololololololololololololololololololololololololololololololololol' (with space). Your task is to help John create a function that will take in the string of his message without the 'lololol' part and return a string containing a tweet according to John's specifications. | D35: """ def pad_answer(s): space = 140-len(s) if space == 0: return s if space%2==0: return s+" "+"lo"*((space-2)//2) + "l" else: return s+"lo"*(space//2) + "l" """
A36: 17355 | B36: Create a function that accepts a single word as input and transforms it into pig latin. The rules for this simplified pig latin conversion are as follows: Move the first letter of the word to the end and then append the string 'ay' to it. For instance, if the input is 'python", the output should be 'ythonpay'. | C36: """ def pig_latin(word): return word[1:]+word[0]+'ay' """
A37: 17356 | B37: Create a function that accepts a string as an input. The function should convert all the uppercase characters in the string to lowercase and all the lowercase characters to uppercase. For instance, if the input string is "This is a Test", the function should return "tHIS IS A tEST". | D37: """ def swap(s): res = "" for c in s: if c in "ABCDEFGHIJKLMNOPQRSTUVWXYZ": res+=c.lower() elif c in "abcdefghijklmnopqrstuvwxyz": res+=c.upper() else: res+=c return res """
A38: 17357 | B38: In this task, you are required to convert a sentence into pig latin. Pig latin is a secret language formed by altering the letters in the words. The Python function 'split()' can be used to break down a sentence into individual words. For instance, "Hello World".split() will return ["Hello","World"]. You need to write a function that takes a sentence as input and converts it into pig latin. To keep things simple, the input sentences will not contain any punctuation. | C38: def pig_latin(word): return word[1:]+word[0]+'ay' | D38: """ def pig_latin_sentence(sentence): res = "" for word in sentence.split(): res+=pig_latin(word)+" " res = res[:-1] return res """
A39: 17358 | B39: Create a function named 'at_least_n'. This function should accept two parameters: a list of integers and an integer 'n'. The function should return a new list that contains only the integers from the original list that are greater than or equal to 'n'. All the integers smaller than 'n' should be removed from the list. | D39: list1 = list(range(15)) list2 = list(range(100))
A40: 17359 | B40: In the world of computers, understanding binary numbers is essential. This task will test your knowledge of binary numbers and your ability to convert them into decimal numbers. You will be given a list of binary numbers, where each element of the list represents a digit of the binary number. For instance, the binary number 110101 will be represented as [1, 1, 0, 1, 0, 1]. Your task is to write a Python function that converts this binary number into its decimal equivalent. For example, the binary number 110101 is equivalent to 53 in decimal. Please note that there won't be any negative numbers in the input, and you should not hard-code the solution as it will fail for larger test cases.
...

Sheet testcases
A1: tid | B1: pid | C1: input | D1: output
A2: 106586 | B2: 17312 | C2: result | D2: ans
A3: 106587 | B3: 17312 | C3: no_code | D3: False
A4: 106607 | B4: 17315 | C4: factorial(5) | D4: 120
A5: 106608 | B5: 17315 | C5: factorial(0) | D5: 1
A6: 106609 | B6: 17315 | C6: factorial(1) | D6: 1
A7: 106610 | B7: 17315 | C7: factorial(3) | D7: 6
A8: 106611 | B8: 17315 | C8: factorial(120) | D8: 6689502913449127057588118054090372586752746333138029810295671352301633557244962989366874165271984981308157637893214090552534408589408121859898481114389650005964960521256960000000000000000000000000000
A9: 106612 | B9: 17315 | C9: factorial(2) | D9: 2
A10: 106613 | B10: 17315 | C10: factorial(121) | D10: 809429852527344373968162284544935082997082306309701607045776233628497660426640521713391773997910182738287074185078904956856663439318382745047716214841147650721760223072092160000000000000000000000000000
A11: 106617 | B11: 17317 | C11: result | D11: ans
A12: 106618 | B12: 17317 | C12: no_code | D12: False
A13: 106619 | B13: 17318 | C13: x | D13: newx
... A315: 107005 | B315: 17390 | C315: stop_time(27) | D315: 111
A316: 107006 | B316: 17390 | C316: stop_time(factorial(120)) | D316: 976
A317: 107007 | B317: 17390 | C317: stop_time(81) | D317: 22
A318: 107008 | B318: 17390 | C318: stop_time(15) | D318: 17
A319: 107009 | B319: 17390 | C319: stop_time(665215) | D319: 441
A320: 107018 | B320: 17393 | C320: smallestNsq(50) | D320: 8
A321: 107019 | B321: 17393 | C321: smallestNsq(12000) | D321: 110
A322: 107020 | B322: 17393 | C322: smallestNsq(1) | D322: 2
A323: 107021 | B323: 17393 | C323: smallestNsq(10000) | D323: 101
A324: 107079 | B324: 17397 | C324: pattern(1) | D324: "1"
A325: 107080 | B325: 17397 | C325: pattern(2) | D325: "122"
A326: 107081 | B326: 17397 | C326: pattern(8) | D326: "122333444455555666666777777788888888"
A327: 107082 | B327: 17397 | C327: pattern(20) | D327: "122333444455555666666777777788888888999999999101010101010101010101111111111111111111111121212121212121212121212131313131313131313131313131414141414141414141414141414151515151515151515151515151515161616161616161616161616161616161717171717171717171717171717171717181818181818181818181818181818181818191919191919191919191919191919191919192020202020202020202020202020202020202020"
A328: 107089 | B328: 17400 | C328: triangle3(6) | D328: " 1\n 12\n 123\n 1234\n 12345\n123456"
... A343: 107202 | B343: 17422 | C343: convert16Bit(1256) | D343: "0000010011101000"

Sheet buggy_submissions
A1: sid | B1: pid | C1: code | D1: failing_testcases | E1: passing_testcases
A2: 1 | B2: 17311 | C2: """ store the final answer in a variable named result """ fahre = eval(input(enter the temperatur in fahrenheit)) result = ( fahre - 32 ) * 5 / 9 | D2: ['106584", '106585'] | E2: []
A3: 2 | B3: 17312 | C3: """ store the final answer in a variable named result """ name = input("Enter your name:") age = input("Enter your age:") str.(name) str.(age) result = "My friend " + name + " is " + age + " years old." print(result) | D3: ['106586", '106587'] | E3: []
A4: 3 | B4: 17312 | C4: """ store the final answer in a variable named result """ name = int(input("enter name:")) age = int(input("enter age:")) result = "My friend" + (name) + " is " + (age) + "years old." print(result) | D4: ['106586", '106587'] | E4: []
A5: 4 | B5: 17312 | C5: x=eval(input("Enter your age:")) y=str(input("Enter your name:")) result=("My friend",y,"is",x,"years old.") | D5: ['106586'] | E5: ['106587']
A6: 5 | B6: 17312 | C6: n = str(input("Enter your name:")) a = str(input("Enter your age:")) result = "My friend " + str(n) " is " + str(a) " years old." print(result) | D6: ['106586", '106587'] | E6: []
A7: 6 | B7: 17312 | C7: """ store your answer in a variable named result """ name=eval(input('enter your name')) age=eval(input('enter your age')) result=("My friend", name, "is", age "years old.") print(result) | D7: ['106586", '106587'] | E7: []
A8: 7 | B8: 17312 | C8: name = input("Enter your name: ") age = eval(input("Enter your age: ") result = "My friend "+name+" is "+age+" years old print(result) | D8: ['106586", '106587'] | E8: []
A9: 8 | B9: 17312 | C9: """ store your answer in a variable named result """ name = input() age = input() result = "My friend "+ name+" is "+age+" years old." | D9: ['106586", '106587'] | E9: []
A10: 9 | B10: 17313 | C10: """ store your answer in a variable named result """ a = input("hi") print(a) | D10: ['106588'] | E10: ['106589']
A11: 10 | B11: 17314 | C11: def count_substring(string): ans = 0 positionA = -1 for count in range(string.count('A')): positionA = string.find('A", positionA + 1) ans += string.count('X", positionA + 1) return ans | D11: ['106603", '106604", '106605", '106606'] | E11: ['106590", '106591", '106592", '106593", '106594", '106595", '106596", '106597", '106598", '106599", '106600", '106601", '106602']
A12: 11 | B12: 17314 | C12: def count_substring(string): lst = list(string) ans = 0 for i in range(len(lst)): if lst[i] == 'A': ans += lst[i:].count('X') if lst[i:].count('A') == 0: return ans return ans | D12: ['106601", '106603", '106604", '106605", '106606'] | E12: ['106590", '106591", '106592", '106593", '106594", '106595", '106596", '106597", '106598", '106599", '106600", '106602']
A13: 12 | B13: 17314 | C13: def count_substring(string): k = string.split("A") l = "" a = l.join(k) numA = len(string) - len(a) s = -1 ans = 0 while s > -(len(string)): if string[s] == "X": ans += numA elif string[s] == "A": numA -= 1 else: ans = ans s -= 1 return ans | D13: ['106606'] | E13: ['106590", '106591", '106592", '106593", '106594", '106595", '106596", '106597", '106598", '106599", '106600", '106601", '106602", '106603", '106604", '106605']
... A367: 366 | B367: 17422 | C367: def convert16Bit(decimal): ans = bin(decimal)[2:] res = ans.zfill(16) | D367: ['107200", '107201", '107202'] | E367: []

Sheet correct_submissions
A1: sid | B1: pid | C1: code
A2: 367 | B2: 17311 | C2: """ store the final answer in a variable named result """ number1 = eval(input("Enter a temperature in Fahreheit: ")) result = (number1-32)*5/9 print("The temperature in Celsius is", result)
A3: 368 | B3: 17311 | C3: """ store the final answer in a variable named result """ fah = float(input("enter temperature")) #T(C) = (T(F) - 32) 5/9 result = (fah - 32) * 5/9 print(result)
A4: 369 | B4: 17311 | C4: """ store the final answer in a variable named result """ result = (int(input(""))-32)*5/9
A5: 370 | B5: 17311 | C5: """ store the final answer in a variable named result """ Fah = eval(input("Enter Fahrenheit: ")) result = (Fah-32)*(5/9) print(result)
A6: 371 | B6: 17311 | C6: """ store the final answer in a variable named result """ fahrenheit = eval(input("Enter Temperature in Fahrenheit:")) celcius = (fahrenheit - 32) * 5 / 9 result = celcius print(result)
A7: 372 | B7: 17311 | C7: """ store the final answer in a variable named result """ T = int(input("Enter temperature in Fahreheit:")) result = (T-32)*(5/9) print(result)
A8: 373 | B8: 17311 | C8: F=float(input("")) result=(F - 32) * 5/9
A9: 374 | B9: 17311 | C9: """ store the final answer in a variable named result """ F=int(input("Enter temperature in Fahrenheit:")) result=(F-32)*(5/9) print(result)
A10: 375 | B10: 17311 | C10: """ store the final answer in a variable named result """ f = eval(input("Enter temperature in Fahrenheit:")) result = (f - 32) * (5/9) print(result)
A11: 376 | B11: 17311 | C11: """ store the final answer in a variable named result """ F=int(input("Temperature in Fahrenheit:")) C=(F-32)*5/9 result=C print(result)
A12: 377 | B12: 17311 | C12: """ store the final answer in a variable named result """ f=float(input("enter temperature")) result = (f-32)*5/9 print (result)
A13: 378 | B13: 17311 | C13: """ store the final answer in a variable named result """ x=eval(input("Enter temperature in Fahrenheit:")) result=(x-32)*(5/9) print(result)
... A5856: 6221 | B5856: 17422 | C5856: def convert16Bit(decimal): s = '{0:b}'.format(decimal).zfill(16) return s

Sheet gpt4_1
A1: pid | B1: sid | C1: student_code | D1: repaired_code | E1: feedback | F1: num_iteration | G1: isRepairSuccess | H1: # feedback | I1: # TP Valid | J1: # FP Extra | K1: # FP Invalid | L1: # FP Hallucinate | M1: # FN Missed
A2: 17311 | B2: 1 | C2: """ store the final answer in a variable named result """ fahre = eval(input(enter the temperatur in fahrenheit)) result = ( fahre - 32 ) * 5 / 9 | D2: """ store the final answer in a variable named result """ fahre = eval(input('enter the temperature in fahrenheit')) result = ( fahre - 32 ) * 5 / 9 | E2: [ { "line_number": "2", "feedback": "The input prompt should be a string. You forgot to put quotes around the prompt. Always remember to enclose your strings in quotes.", "category": "TP" }] | F2: 1 | G2: TRUE | H2: 1 | I2: 1
A3: 17312 | B3: 2 | C3: """ store the final answer in a variable named result """ name = input("Enter your name:") age = input("Enter your age:") str.(name) str.(age) result = "My friend " + name + " is " + age + " years old." print(result) | D3: """ store the final answer in a variable named result """ name = input("Enter your name:") age = input("Enter your age:") result = "My friend " + name + " is " + age + " years old." print(result) | E3: [ { "line_number": "4", "feedback": "You don't need to convert the 'name' and 'age' variables to string using 'str.' function. The 'input' function in Python always returns a string. So, you can directly use the 'name' and 'age' variables in the concatenation operation.", "category": "TP" } ] | F3: 1 | G3: TRUE | H3: 1 | I3: 1
A4: 17312 | B4: 3 | C4: """ store the final answer in a variable named result """ name = int(input("enter name:")) age = int(input("enter age:")) result = "My friend" + (name) + " is " + (age) + "years old." print(result) | D4: """ store the final answer in a variable named result """ name = input("enter name:") age = input("enter age:") result = "My friend " + name + " is " + age + " years old." print(result) | E4: [ { "line_number": "2", "feedback": "You should not convert the name input to an integer. The name is a string, not a number.", "category": "TP" }, { "line_number": "3", "feedback": "You do not need to convert the age input to an integer. Although age is a number, you are using it as a string in the final message.", "category": "TP" }, { "line_number": "4", "feedback": "You need to add spaces in your string to separate the words properly. Also, you do not need to put parentheses around the variables name and age.", "category": "TP" } ] | F4: 1 | G4: TRUE | H4: 3 | I4: 3
A5: 17312 | B5: 4 | C5: x=eval(input("Enter your age:")) y=str(input("Enter your name:")) result=("My friend",y,"is",x,"years old.") | D5: y = input("Enter your name:") x = eval(input("Enter your age:")) result = "My friend " + y + " is " + str(x) + " years old." | E5: [ { "line_number": "1", "feedback": "The order of input prompts should match with the order of inputs provided. In this case, name should be asked before age.", "category": "TP" }, { "line_number": "4", "feedback": "The result string should be a single string. You should use the "+" operator to concatenate strings instead of comma. Also, the age should be converted to string before concatenating.", "category": "TP" } ] | F5: 1 | G5: TRUE | H5: 2 | I5: 2
A6: 17312 | B6: 5 | C6: n = str(input("Enter your name:")) a = str(input("Enter your age:")) result = "My friend " + str(n) " is " + str(a) " years old." print(result) | D6: n = str(input("Enter your name:")) a = str(input("Enter your age:")) result = "My friend " + str(n) + " is " + str(a) + " years old." print(result) | E6: [ { "line_number": "3", "feedback": "You forgot to add the "+" operator to concatenate the strings. Remember, in Python, you need to use "+" to join strings together.", "category": "TP" }] | F6: 1 | G6: TRUE | H6: 1 | I6: 1
A7: 17312 | B7: 6 | C7: """ store your answer in a variable named result """ name=eval(input('enter your name')) age=eval(input('enter your age')) result=("My friend", name, "is", age "years old.") print(result) | D7: """ store your answer in a variable named result """ name=eval(input('enter your name')) age=eval(input('enter your age')) result="My friend " + name + " is " + str(age) + " years old." print(result) | E7: [ { "line_number": "4", "feedback": "You were trying to concatenate strings and integer which is not possible in python. Also, you were trying to store the result as a tuple instead of a string. You should convert the age to string and concatenate all the parts of the sentence to form a single string.", "category": "TP" }] | F7: 1 | G7: TRUE | H7: 1 | I7: 1
A8: 17312 | B8: 7 | C8: name = input("Enter your name: ") age = eval(input("Enter your age: ") result = "My friend "+name+" is "+age+" years old print(result) | D8: name = input("Enter your name: ") age = input("Enter your age: ") result = "My friend "+name+" is "+age+" years old." print(result) | E8: [ { "line_number": "2", "feedback": "You should use the input function to get the age as a string. The eval function is not necessary here.", "category": "TP" }, { "line_number": "3", "feedback": "You missed closing the double quotes at the end of the string. Always ensure to close any opened quotes.", "category": "TP" }, { "line_number": "3", "feedback": "You forgot to add a full-stop at the end of the string", "category": "FN" } ] | F8: 1 | G8: TRUE | H8: 2 | I8: 2 | M8: 1
A9: 17312 | B9: 8 | C9: """ store your answer in a variable named result """ name = input() age = input() result = "My friend "+ name+" is "+age+" years old." | D9: name = input() age = input() result = "My friend "+ name+" is "+age+" years old." print(result) | E9: [ { "line_number": "2", "feedback": "The input prompt should be a string. You forgot to put quotes around the prompt. Always remember to enclose your strings in quotes.", "category": "FP-E" }, { "line_number": "3", "feedback": "The input prompt should be a string. You forgot to put quotes around the prompt. Always remember to enclose your strings in quotes.", "category": "FP-E" }, { "line_number": "5", "feedback": "You need to print the result", "category": "FN" } ] | F9: 1 | G9: FALSE | H9: 2 | J9: 2 | M9: 1
A10: 17313 | B10: 9 | C10: """ store your answer in a variable named result """ a = input("hi") print(a) | D10: radius = float(input("Enter the radius of the cylinder: ")) height = float(input("Enter the height of the cylinder: ")) result = 3.14159 * radius ** 2 * height print(result) | E10: [ { "line_number": "1", "feedback": "You should prompt the user to input the radius of a cylinder, not just print "hi". Use the input function to get user input and convert it to a float.", "category": "TP" }, { "line_number": "2", "feedback": "You should also prompt the user to input the height of the cylinder. Again, use the input function and convert the input to a float.", "category": "TP" }, { "line_number": "3", "feedback": "You need to calculate the volume of the cylinder using the formula πr²h and store the result in a variable named "result".", "category": "TP" }, { "line_number": "4", "feedback": "Finally, you should print out the calculated volume, not the input radius.", "category": "TP" } ] | F10: 1 | G10: TRUE | H10: 4 | I10: 4
A11: 17314 | B11: 10 | C11: def count_substring(string): ans = 0 positionA = -1 for count in range(string.count('A')): positionA = string.find('A", positionA + 1) ans += string.count('X", positionA + 1) return ans | D11: def count_substring(string): ans = 0 positionA = -1 for count in range(string.count('A')): positionA = string.find('A", positionA + 1) ans += int(string[positionA + 1:].find('X') != -1) return ans | E11: [ { "line_number": "6", "feedback": "Instead of counting all the X characters from the position of A to the end of the string, you should check if there is an X character after A. This can be done by using the find method on the substring of the string that starts after A. If the find method returns -1, it means there is no X character after A, otherwise there is. You can convert this boolean to an integer and add it to ans.'", "category": "FP-I" }, { "line_number": "4", "feedback": "You are not correctly counting the substrings starting with 'A' and ending with 'X'. You need to count 'X's in the substring starting from 'A' until the end of the string, for each 'A' in the string. However, the count of 'X's should be cumulative for each 'A' found in the string. This can be done by iterating over the string in reverse order and for each 'X' found, increment a counter. For each 'A' found, add the current count of 'X's to the answer.", "category": "FN" }] | F11: 1 | G11: FALSE | H11: 1 | K11: 1 | M11: 1
A12: 17314 | B12: 11 | C12: def count_substring(string): lst = list(string) ans = 0 for i in range(len(lst)): if lst[i] == 'A': ans += lst[i:].count('X') if lst[i:].count('A') == 0: return ans return ans | D12: def count_substring(string): lst = list(string) ans = 0 for i in range(len(lst)): if lst[i] == 'A': ans += lst[i:].count('X') return ans | E12: [ { "line_number": "6", "feedback": "The condition to check if there are no more "A" in the remaining string is not necessary. The loop will naturally end when it has traversed the entire string. Removing this condition will not affect the logic of the program and will make it pass all the test cases.'", "category": "TP" }, { "line_number": "5", "feedback": "The logic of the code is incorrect. The count of 'X' after each 'A' is not the correct way to count the substrings that start with 'A' and end with 'X'. Instead, you should increment a counter every time you encounter an 'A", and for each 'X' you encounter, add the current count of 'A's to the answer. This is because each 'X' can pair with any 'A' that came before it to form a valid substring.", "category": "FN" } ] | F12: 1 | G12: FALSE | H12: 1 | I12: 1 | M12: 1
A13: 17314 | B13: 12 | C13: def count_substring(string): k = string.split("A") l = "" a = l.join(k) numA = len(string) - len(a) s = -1 ans = 0 while s > -(len(string)): if string[s] == "X": ans += numA elif string[s] == "A": numA -= 1 else: ans = ans s -= 1 return ans | D13: def count_substring(string): numA = 0 ans = 0 for s in string: if s == "A": numA += 1 elif s == "X": ans += numA return ans | E13: [ { "line_number": "2", "feedback": "You don't need to split the string. Instead, you can iterate over it directly.", "category": "FP-E" }, { "line_number": "3", "feedback": "The variable 'l' and the join operation are not necessary. You can count the number of 'A's directly in the loop.", "category": "FP-E" }, { "line_number": "5", "feedback": "You don't need to calculate the length of the string and subtract it from the length of 'a'. You can count the number of 'A's directly in the loop.", "category": "FP-E" }, { "line_number": "6", "feedback": "You don't need to use a while loop with a negative index. You can use a for loop to iterate over the string.", "category": "FP-E" }, { "line_number": "7", "feedback": "You don't need to check if the character is 'X' in the loop. Instead, you can increment the count of 'A's when you encounter an 'A' and add the count of 'A's to the answer when you encounter an 'X'.", "category": "TP" }, { "line_number": "9", "feedback": "You don't need to decrement the count of 'A's when you encounter an 'A'. Instead, you should increment the count of 'A's.", "category": "TP" }, { "line_number": "11", "feedback": "You don't need to assign 'ans' to itself. This line can be removed.", "category": "FP-E" } ] | F13: 1 | G13: TRUE | H13: 7 | I13: 2 | J13: 5
A14: 17314 | B14: 13 | C14: def count_substring(s): ans = 0 for i in range (0, len(s)): ca = 0 cx = 0 n = 0 if s[i] == 'A': ca = 1 if i == (len(s)-1): if s[i] == 'X': cx = 1 else: for x in s[i+1:len(s)]: if x == 'X': cx +=1 n = ca * cx ans += n return ans | D14: def count_substring(s): ans = 0 ca = 0 for i in range (0, len(s)): if s[i] == 'A': ca += 1 elif s[i] == 'X': ans += ca return ans | E14: [ { "line_number": "4", "feedback": "You don't need to initialize 'ca", 'cx", and 'n' inside the loop. Only 'ca' is required and it should be initialized before the loop."", "category": "TP" }, { "line_number": "6", "feedback": "The condition 'if i == (len(s)-1):' is not necessary. You should increment 'ca' each time you encounter 'A' and increment 'ans' by 'ca' each time you encounter 'X'."", "category": "TP" }, { "line_number": "8", "feedback": "The inner loop is not necessary. You can accomplish the task using only one loop."", "category": "TP" }, { "line_number": "9", "feedback": "You don't need to keep a count of 'X'. Instead, each time you encounter 'X", add the current count of 'A' to 'ans'."", "category": "TP" }, { "line_number": "12", "feedback": "The calculation of 'n' is not required. You can directly add 'ca' to 'ans' each time you encounter 'X'."", "category": "TP" } ] | F14: 1 | G14: TRUE | H14: 5 | I14: 5
A15: 17314 | B15: 14 | C15: def count_substring(string): numbera=0 count=0 for i in range(len(string)): if string[i]=="A": count+=1 if string[i]=="X": count+=1 | D15: def count_substring(string): numbera=0 count=0 for i in range(len(string)): if string[i]=="A": numbera+=1 if string[i]=="X": count+=numbera return count | E15: [ { "line_number": "2", "feedback": "Indentation is important in Python. The body of your function should be indented.'", "category": "FP-H" }, { "line_number": "5", "feedback": "You should increment the count of "A" when you encounter an "A", not the total count.'", "category": "TP" }, { "line_number": "7", "feedback": "When you encounter an "X", you should add the count of "A"s to the total count, not just increment it by one.'", "category": "TP" }, { "line_number": "8", "feedback": "Your function should return the count at the end.'", "category": "TP" } ] | F15: 1 | G15: TRUE | H15: 4 | I15: 3 | L15: 1
A16: 17314 | B16: 15 | C16: def count_substring(string): ans = 0 for i in range(len(string)): if string[i] == 'A': rightstr = string[i+1:] x = rightstr.count('X') ans = ans + x return ans | D16: def count_substring(string): ans = 0 for i in range(len(string)): if string[i] == 'A': rightstr = string[i+1:].split('A')[0] x = rightstr.count('X') ans = ans + x return ans | E16: [ { "line_number": "6", "feedback": "You are counting all the Xs after an A. But you should only count the Xs until the next A is found. You can use the split() function to get the substring from the current index to the next A.'", "category": "FP-I" }, { "line_number": "6", "feedback": "You are counting all the 'X's after each 'A'. However, you should consider that each 'A' starts a new substring. Therefore, you need to keep a count of 'A's and for each 'X' you find, add the current count of 'A's to the answer.", "category": "FN" }] | F16: 1 | G16: FALSE | H16: 1 | K16: 1 | M16: 1
A17: 17314 | B17: 16 | C17: def count_substring(string): count=0 for i in range(0,len(string)): n=i while n<len(string): if string[i]=='A' and string[n]=='X': count=count+1 n=n+1 else: count=count n=n+1 return count | D17: def count_substring(string): count = 0 for i in range(0, len(string)): if string[i] == 'A': for n in range(i+1, len(string)): if string[n] == 'X': count += 1 return count | E17: [ { "line_number": "5", "feedback": "You should only increment the count when you find a substring that starts with "A" and ends with "X". So, you should start your inner loop only when you find an "A".", "category": "FP-E" }, { "line_number": "7", "feedback": "The inner loop should start from the next character after "A", not from the same character.", "category": "FP-E" }, { "line_number": "9", "feedback": "You should increment the count and break the loop as soon as you find an "X", because you have found a valid substring. You do not need to continue checking the rest of the string.", "category": "FP-E" }, { "line_number": "15", "feedback": "You do not need the else statement here. If the condition in the if statement is not met, the loop will automatically continue to the next iteration.", "category": "FP-E" } ] | F17: 1 | G17: FALSE | H17: 4 | J17: 4 | M17: 1
A18: 17315 | B18: 17 | C18: def factorial(n): ans = 0 for ans in range(0, n+1, 1) ans = n * ans return ans | D18: def factorial(n): ans = 1 for i in range(1, n+1): ans *= i return ans | E18: [ { "line_number": "2", "feedback": "You should initialize "ans" to 1, not 0. Because anything multiplied by 0 is 0, your function will always return 0.'", "category": "TP" }, { "line_number": "3", "feedback": "You should iterate from 1 to n (inclusive), not from 0 to n. Also, you need to include a colon at the end of the for loop.'", "category": "TP" }, { "line_number": "4", "feedback": "You should multiply "ans" by the current number "i", not "n". Also, use the "*=" operator to update the value of "ans".'", "category": "TP" } ] | F18: 1 | G18: TRUE | H18: 3 | I18: 3
A19: 17315 | B19: 18 | C19: def factorial(n): ans=1 while n>0: ans*=n n-1 return ans | D19: def factorial(n): ans=1 for i in range(1, n+1): ans*=i return ans | E19: [ { "line_number": "3", "feedback": "You should use a for loop as per the problem statement, not a while loop. Also, you forgot to update the value of n in the loop. It should be n = n - 1, not just n-1.'", "category": "TP" }, { "line_number": "4", "feedback": "In your loop, you should multiply ans by i, where i ranges from 1 to n. This is because the factorial of a number is the product of all positive integers up to that number.'", "category": "TP" } ] | F19: 1 | G19: TRUE | H19: 2 | I19: 2
A20: 17315 | B20: 19 | C20: def factorial(n): a = 0 while n != 1: if n % 2 == 0: n = n // 2 else: n = (3 * n) + 1 a += 1 return a | D20: def factorial(n): result = 1 for i in range(1, n+1): result *= i return result | E20: [ { "line_number": "2", "feedback": "You should initialize your result variable to 1, not 0. Because you are calculating a product, starting with 0 will always result in 0.'", "category": "TP" }, { "line_number": "3", "feedback": "You should be using a for loop to calculate the factorial, not a while loop. The while loop you have written is calculating something else.'", "category": "TP" }, { "line_number": "4", "feedback": "Your logic for updating the variable n is incorrect. You should be decrementing n by 1 each time, not dividing by 2 or multiplying by 3.'", "category": "TP" }, { "line_number": "6", "feedback": "You should be multiplying your result variable by i each time through the loop, not adding 1 to it.'", "category": "TP" }, { "line_number": "7", "feedback": "You should be returning your result variable, not a.'", "category": "TP" } ] | F20: 1 | G20: TRUE | H20: 5 | I20: 5
A21: 17315 | B21: 20 | C21: def factorial(n): if n < 0: ans = "Invalid Input! " elif n == 0: ans = 1 else: for i in range(1, n + 1): ans *= i return ans | D21: def factorial(n): ans = 1 if n < 0: ans = "Invalid Input! " elif n == 0: ans = 1 else: for i in range(1, n + 1): ans *= i return ans | E21: [ { "line_number": "2", "feedback": "You forgot to initialize the variable "ans". It should be initialized to 1 before the loop starts. This is because the variable "ans" is used in the loop for multiplication, and any number multiplied by 1 remains the same. If "ans" is not initialized and you try to use it in the loop, it will cause an error because "ans" would not have a value yet.'", "category": "TP" } ] | F21: 1 | G21: TRUE | H21: 1 | I21: 1
A22: 17315 | B22: 21 | C22: def factorial(n): if n==0: ans=1 else: a=1 while a<n+1: ans=1 ans=ans*a a+=1 return ans | D22: def factorial(n): ans = 1 for a in range(1, n+1): ans = ans * a return ans | E22: [ { "line_number": "3", "feedback": "You don't need to check if n==0. The for loop will handle it correctly."", "category": "FP-H" }, { "line_number": "5", "feedback": "You should use a 'for' loop as per the problem statement, not a 'while' loop."", "category": "TP" }, { "line_number": "7", "feedback": "You're resetting ans to 1 in every iteration of the loop. You should initialize ans to 1 before the loop starts."", "category": "TP" }, { "line_number": "8", "feedback": "In the loop, you should multiply the current value of ans by a, not set ans equal to a."", "category": "TP" } ] | F22: 1 | G22: TRUE | H22: 4 | I22: 3 | L22: 1
A23: 17316 | B23: 22 | C23: """ store your answer in a variable named result """ """ store your answer in a variable named result """ digit = eval(input("Enter int: ")) ones = digit % 10 tens = (digit // 10) % 10 hundred = (digit // 100) % 10 result = ones + tens print(sum) | D23: """ store your answer in a variable named result """ digit = eval(input("Enter int: ")) ones = digit % 10 tens = (digit // 10) % 10 hundreds = (digit // 100) % 10 result = ones + tens + hundreds print(result) | E23: [ { "line_number": "6", "feedback": "You have made a typo in the variable name. It should be "hundreds" instead of "hundred".'", "category": "FP-E" }, { "line_number": "7", "feedback": "You need to add the hundreds place digit to the result as well. So, it should be "result = ones + tens + hundreds".'", "category": "TP" }, { "line_number": "8", "feedback": "You should print the variable "result" instead of the function "sum".'", "category": "TP" } ] | F23: 1 | G23: TRUE | H23: 3 | I23: 2 | J23: 1
A24: 17316 | B24: 23 | C24: """ store your answer in a variable named result """ | D24: num = input("Enter a number in range [0,999]: ") num = int(num) result = 0 while num > 0: digit = num % 10 result += digit num = num // 10 print("The sum of the digits is", result) | E24: [ { "line_number": "1", "feedback": "You need to start by prompting the user to input an integer within the range of 0 to 999. You can use the input function for this.'", "category": "TP" }, { "line_number": "2", "feedback": "You need to convert the input to an integer using the int function.'", "category": "TP" }, { "line_number": "3", "feedback": "You need to initialize a variable named result to store the sum of the digits.'", "category": "TP" }, { "line_number": "4", "feedback": "You need to use a while loop to keep extracting and adding the digits of the number until the number becomes 0.'", "category": "TP" }, { "line_number": "5", "feedback": "You can use the modulus operator (%) to extract the last digit of the number.'", "category": "TP" }, { "line_number": "6", "feedback": "You need to add the extracted digit to the result.'", "category": "TP" }, { "line_number": "7", "feedback": "You can use the floor division operator (//) to remove the last digit from the number.'", "category": "TP" }, { "line_number": "8", "feedback": "Finally, you need to print the result.'", "category": "TP" } ] | F24: 1 | G24: TRUE | H24: 8 | I24: 8
A25: 17316 | B25: 24 | C25: integer = str(input("Enter an integer range [0,999]: ")) result = str[0] + str[1] + str[2] print(result) | D25: integer = int(input("Enter an integer range [0,999]: ")) result = integer // 100 + (integer % 100) // 10 + integer % 10 print("The sum of the digits is", result) | E25: [ { "line_number": "1", "feedback": "You should convert the input to integer instead of string, as we are dealing with numbers here.'", "category": "TP" }, { "line_number": "2", "feedback": "You are trying to access elements of string "str" which is incorrect. You should be using the variable "integer". Also, you need to extract the digits from the number using "%" and "//" operators and then add them.'", "category": "TP" }, { "line_number": "3", "feedback": "The print statement should display a proper message along with the result.'", "category": "FP-E" } ] | F25: 1 | G25: TRUE | H25: 3 | I25: 2 | J25: 1
A26: 17316 | B26: 25 | C26: """ store your answer in a variable named result """ ans = result % 10 result = result /10 ans += result % 10 result = result /10 ans += result | D26: result = int(input()) ans = result % 10 result = result // 10 ans += result % 10 result = result // 10 ans += result | E26: [ { "line_number": "1", "feedback": "You forgot to take the user\'s input. You should assign the input to the variable \'result\' before performing operations on it.'", "category": "TP" }, { "line_number": "2", "feedback": "You should use \'//\' for integer division instead of \'/\'. The \'//\' operator performs floor division which returns the largest possible integer.'", "category": "TP" }, { "line_number": "4", "feedback": "You should use \'//\' for integer division instead of \'/\'. The \'//\' operator performs floor division which returns the largest possible integer.'", "category": "TP" }, { "line_number": "6", "feedback": "You should assign the final sum 'ans' back to 'result' as per the problem statement.", "category": "FN" } ] | F26: 1 | G26: FALSE | H26: 3 | I26: 3 | M26: 1
A27: 17317 | B27: 26 | C27: """ store the final answer in a variable named result """ integar = int(input("Enter an integar:")) result = integar%2 print(result == 0) | D27: """ store the final answer in a variable named result """ integar = int(input("Enter an integar:")) result = integar%2 == 0 print(result) | E27: [ { "line_number": "3", "feedback": "The result variable should store whether the number is even or not. So, you should assign the comparison (integar%2 == 0) to the result variable, not just the remainder of the division.'", "category": "TP" }] | F27: 1 | G27: TRUE | H27: 1 | I27: 1
A28: 17318 | B28: 27 | C28: x=1 y=2 x,y=y,x | D28: x, y = y, x | E28: [ { "line_number": "1", "feedback": "You do not need to reassign the values of x and y. They are already defined in the prefix.'", "category": "TP" }, { "line_number": "2", "feedback": "You do not need to reassign the values of x and y. They are already defined in the prefix.'", "category": "TP" } ] | F28: 1 | G28: TRUE | H28: 2 | I28: 2
A29: 17318 | B29: 28 | C29: x="newy" y="newx" x,y=x,y print(x) print(y) | D29: x, y = y, x print(x) print(y) | E29: [ { "line_number": "1", "feedback": "You were on the right track, but you made a mistake when trying to swap the values of x and y. You don't need to assign new strings to x and y before swapping their values. You can directly swap the values using the syntax "x, y = y, x". This will assign the value of y to x and the value of x to y.'", "category": "TP" }, { "line_number": "2", "feedback": "The print statements are correct. They will print the swapped values of x and y.'", "category": "FP-E" } ] | F29: 1 | G29: TRUE | H29: 2 | I29: 1 | J29: 1
A30: 17318 | B30: 29 | C30: x = 5 y = 9 x, y = y , x newx = x newy = y | D30: x, y = y , x | E30: [ { "line_number": "1", "feedback": "You have correctly used the tuple unpacking feature of Python to swap the values of x and y. However, you are reassigning the values of x and y at the beginning of your code, which is not necessary and is causing your code to fail. The values of x and y are already provided in the prefix. You should remove the first two lines of your code.'", "category": "TP" }, { "line_number": "3", "feedback": "The variables newx and newy are not needed in this case. The swapping of values should be reflected in the original variables x and y. You should remove these lines.'", "category": "TP" } ] | F30: 1 | G30: TRUE | H30: 2 | I30: 2
A31: 17318 | B31: 30 | C31: x, y = 2*y, x | D31: x, y = y, x | E31: [ { "line_number": "1", "feedback": "You were on the right track with using tuple unpacking to swap the values of x and y. However, you multiplied y by 2 in your code, which is not needed. Simply assign x to y and y to x to swap their values.'", "category": "TP" }] | F31: 1 | G31: TRUE | H31: 1 | I31: 1
